**出错了怎么办？**

在编写程序的过程中，我们不能够保证永远不会出错，既然程序总会有问题，我们就要用适当的方法去解决问题，比如`int('BMW')`他就或报错,这就是异常了。

现在让我们回到我们之前创建的第一个小游戏

```py
temp = input('不如来猜一下我现在心里想的数字呗')
guess = int(temp)
if guess == 6:
    pirnt('猜中了又如何，买得起宝马吗？')
else:
    print('猜错了，我想的是6')
print('游戏结束了，不玩了')
```
这个脚本呢，当用户输入的是正确的就不会有任何问题了，但只要用户输入的是一个非数字，那么这个代码就狗带了。你看
```py
不如来猜一下我现在心里想的数字呗 d
Traceback (most recent call last):
 File "D:/my_script/pyscript/work33.py", line 3, in <module>
 guess = int(temp)
ValueError: invalid literal for int() with base 10: 'd'
```
这里呢当我们输入的为字母d时，Python就跑出了一个ValueError的错误。

这里列举一下Python常见的异常

1、**AssertionError**，断言(assert)失败
```py
a = [1,2,3]
#assert断言，当assert后面的内容为False时报错
assert len(a) <0
```
看报错结果
```py
Traceback (most recent call last):
 File "D:/my_script/pyscript/work33.py", line 2, in <module>
 assert len(a) <0
AssertionError
```
2、**AttributeError**，访问不存在的属性
```py
a= [1,2,3]
#尝试访问列表的pops()方法，当然列表并没有这个方法
a.pops()
```
看报错结果

```py
Traceback (most recent call last):

 File "D:/my_script/pyscript/work33.py", line 2, in <module>

 a.pops()

AttributeError: 'list' object has no attribute 'pops'
```

3、**IndexError**，超出索引范围
```py
a= [1,2,3]
#访问列表的第五项
a[5]
```
查看报错结果
```py
Traceback (most recent call last):

 File "D:/my_script/pyscript/work33.py", line 2, in <module>

 a[5]

IndexError: list index out of range
```
4、**KeyError**，访问字典中不存在的一个关键字

```py
a= {'one':1,'two':2}
a['three']
```
查看报错结果
```py
Traceback (most recent call last):

 File "D:/my_script/pyscript/work33.py", line 2, in <module>

 a['three']

KeyError: 'three'


```
5、**NameError**,访问一个不存在的变量

```py
print(a)
```
查看报错
```py
Traceback (most recent call last):

 File "D:/my_script/pyscript/work33.py", line 1, in <module>

 print(a)

NameError: name 'a' is not defined

```

6、**SytaxError**，Python语法错误

```py
print 'a'
```
查看报错信息
```py
 File "D:/my_script/pyscript/work33.py", line 1

 print 'a'

 ^

SyntaxError: Missing parentheses in call to 'print'
```
7、**TypeError**，不同类型间的无效操作
```py
1+'a'
```
查看报错信息
```py
Traceback (most recent call last):

 File "D:/my_script/pyscript/work33.py", line 1, in <module>

 1+'a'

TypeError: unsupported operand type(s) for +: 'int' and 'str'
```
好了，先缓一缓，知道了这么多报错类型，那我们怎样去捕获异常并进行处理呢？这里我们需要使用到try语句进行处理











